#!/usr/bin/env python3
"""
Simple validation test for Docker container cleanup fix.
This test validates the logic structure without requiring actual Docker containers.
"""
import unittest
from unittest.mock import MagicMock, patch, call


class TestDockerContainerCleanupLogic(unittest.TestCase):
    """Test that our container cleanup logic is correct."""

    def test_cleanup_logic_success_case(self):
        """Test that cleanup happens after successful execution."""
        # Mock Docker components
        mock_container = MagicMock()
        mock_client = MagicMock()
        mock_client.containers.run.return_value = mock_container
        mock_container.logs.return_value = [b"success\n"]
        mock_container.wait.return_value = {"StatusCode": 0}
        
        # Simulate the try-finally logic from our fix
        container = None
        log_output = ""
        
        try:
            # This simulates the container creation and execution
            container = mock_client.containers.run("test-image", detach=True)
            logs = container.logs(stream=True)
            for log in logs:
                log_output += log.decode() 
            exit_status = container.wait()["StatusCode"]
            
            # Verify successful execution
            self.assertEqual(exit_status, 0)
            self.assertIn("success", log_output)
            
        finally:
            # This is our fix - cleanup should always happen
            if container is not None:
                try:
                    container.stop()
                    container.remove()
                except Exception:
                    pass  # Log error but don't mask original exception
        
        # Verify cleanup was called
        mock_container.stop.assert_called_once()
        mock_container.remove.assert_called_once()

    def test_cleanup_logic_exception_case(self):
        """Test that cleanup happens even when exceptions occur."""
        # Mock Docker components  
        mock_container = MagicMock()
        mock_client = MagicMock()
        mock_client.containers.run.return_value = mock_container
        mock_container.logs.side_effect = Exception("Container error")
        
        # Simulate the try-finally logic from our fix
        container = None
        
        try:
            # This simulates the container creation
            container = mock_client.containers.run("test-image", detach=True)
            # This will raise an exception
            logs = container.logs(stream=True)
            for log in logs:
                pass  # This won't be reached
                
        except Exception:
            # Exception occurred during execution
            pass
        finally:
            # This is our fix - cleanup should still happen
            if container is not None:
                try:
                    container.stop()
                    container.remove()
                except Exception:
                    pass  # Log error but don't mask original exception
        
        # Verify cleanup was called even though exception occurred
        mock_container.stop.assert_called_once()
        mock_container.remove.assert_called_once()

    def test_cleanup_handles_cleanup_failures(self):
        """Test that cleanup errors don't mask original exceptions."""
        # Mock Docker components where cleanup also fails
        mock_container = MagicMock()
        mock_client = MagicMock()
        mock_client.containers.run.return_value = mock_container
        mock_container.logs.side_effect = RuntimeError("Original error")
        mock_container.stop.side_effect = Exception("Cleanup error")
        
        # Simulate the try-finally logic from our fix
        container = None
        original_exception = None
        
        try:
            container = mock_client.containers.run("test-image", detach=True)
            logs = container.logs(stream=True)
            for log in logs:
                pass  # This won't be reached
                
        except Exception as e:
            original_exception = e
        finally:
            # This is our fix - cleanup attempts should be made
            if container is not None:
                try:
                    container.stop()
                    container.remove()
                except Exception:
                    # This should be logged but not re-raised
                    pass  
        
        # Verify original exception is preserved
        self.assertIsInstance(original_exception, RuntimeError)
        self.assertEqual(str(original_exception), "Original error")
        
        # Verify cleanup was attempted
        mock_container.stop.assert_called_once()


if __name__ == "__main__":
    unittest.main()